<?xml version="1.0"?>
<robot xmlns:xacro="http://www.ros.org/wiki/xacro">
    <xacro:macro name="gripper" params="">
        <link name="gripper_base">
            <inertial>
                <origin rpy="0 0 0" xyz="0.020482 2.5483E-05 -0.079685" />
                <mass value="0.40081" />
                <inertia ixx="5E-05" ixy="0" ixz="0" iyy="0.00206" iyz="0" izz="0.0011889" />
            </inertial>
        </link>
        <joint name="joint_parent" type="fixed">
            <origin rpy="-1.5708 1.5708 -1.5708" xyz="0.15145 0 0" />
            <parent link="link6" />
            <child link="gripper_base" />
        </joint>
        <link name="finger_left">
            <inertial>
                <origin rpy="0 0 0" xyz="-0.049039 -0.0096764 0.00038868" />
                <mass value="0.061803" />
                <inertia ixx="1.8946E-05" ixy="-1.3168E-06" ixz="-6.5528E-07" iyy="2.7277E-05" iyz="-2.0801E-07" izz="1.1981E-05" />
            </inertial>
            <visual>
                <origin rpy="0 0 0" xyz="-0.05 -0.01 0" />
                <geometry>
                    <!-- <mesh filename="package://airbot_models/meshes/airbot_gripper_2/finger_left.STL" /> -->
                    <box size="0.1 0.02 0.05" />
                </geometry>
                <material name="">
                    <color rgba="1 1 1 1" />
                </material>
            </visual>
            <collision>
                <origin rpy="0 0 0" xyz="-0.05 -0.01 0" />
                <geometry>
                    <!-- <mesh filename="package://airbot_models/meshes/airbot_gripper_2/finger_left.STL" /> -->
                    <box size="0.1 0.02 0.05" />
                </geometry>
            </collision>
        </link>
        <joint name="endleft" type="prismatic">
            <origin rpy="3.14159 -1.5708 0" xyz="0 0.04 0" />
            <parent link="gripper_base" />
            <child link="finger_left" />
            <axis xyz="0 1 0" />
            <limit effort="2" lower="0" upper="0.04" velocity="6.28" />
        </joint>
        <link name="finger_right">
            <inertial>
                <origin rpy="0 0 0" xyz="-0.048742 0.0096369 0.00044322" />
                <mass value="0.0626" />
                <inertia ixx="1.915E-05" ixy="1.343E-06" ixz="-6.8259E-07" iyy="2.7722E-05" iyz="2.0748E-07" izz="1.2248E-05" />
            </inertial>
            <visual>
                <origin rpy="0 0 0" xyz="-0.05 0.01 0" />
                <geometry>
                    <!-- <mesh filename="package://airbot_models/meshes/airbot_gripper_2/finger_right.STL" /> -->
                    <box size="0.1 0.02 0.05" />
                </geometry>
                <material name="">
                    <color rgba="1 1 1 1" />
                </material>
            </visual>
            <collision>
                <origin rpy="0 0 0" xyz="-0.05 0.01 0" />
                <geometry>
                    <!-- <mesh filename="package://airbot_models/meshes/airbot_gripper_2/finger_right.STL" /> -->
                    <box size="0.1 0.02 0.05" />
                </geometry>
            </collision>
        </link>
        <joint name="endright" type="prismatic">
            <origin rpy="3.14159 -1.5708 0" xyz="0 -0.04 0" />
            <parent link="gripper_base" />
            <child link="finger_right" />
            <axis xyz="0 1 0" />
            <limit effort="2" lower="-0.04" upper="0" velocity="6.28" />
        </joint>

    </xacro:macro>
</robot>
