<?xml version="1.0" encoding="utf-8"?>
<!-- This URDF was automatically created by SolidWorks to URDF Exporter! Originally created by Stephen Brawner (brawner@gmail.com) 
     Commit Version: 1.6.0-4-g7f85cfe  Build Version: 1.6.7995.38578
     For more information, please see http://wiki.ros.org/sw_urdf_exporter -->
<robot
  name="airbot_play_v6_1">
  <link
    name="base_link">
    <inertial>
      <origin
        xyz="-0.010729 -0.00017015 0.041712"
        rpy="0 0 0" />
      <mass
        value="0.77705" />
      <inertia
        ixx="0.0008454"
        ixy="-7.5E-06"
        ixz="2.06E-05"
        iyy="0.0011821"
        iyz="-6.4E-06"
        izz="0.0012443" />
    </inertial>
    <visual>
      <origin
        xyz="0 0 0"
        rpy="0 0 0" />
      <geometry>
        <mesh
          filename="package://robot_description/airbot/meshes/base_link.STL" />
      </geometry>
      <material
        name="">
        <color
          rgba="0.75294 0.75294 0.75294 1" />
      </material>
    </visual>
    <collision>
      <origin
        xyz="0 0 0"
        rpy="0 0 0" />
      <geometry>
        <mesh
          filename="package://robot_description/airbot/meshes/base_link.STL" />
      </geometry>
    </collision>
  </link>
  <link
    name="link1">
    <inertial>
      <origin
        xyz="7.9126E-05 -0.002527 -0.0041359"
        rpy="0 0 0" />
      <mass
        value="0.54639" />
      <inertia
        ixx="0.0003462"
        ixy="0"
        ixz="-1.4E-06"
        iyy="0.0002863"
        iyz="-1.1E-06"
        izz="0.0003255" />
    </inertial>
    <visual>
      <origin
        xyz="0 0 0"
        rpy="0 0 0" />
      <geometry>
        <mesh
          filename="package://robot_description/airbot/meshes/link1.STL" />
      </geometry>
      <material
        name="">
        <color
          rgba="0.89804 0.91765 0.92941 1" />
      </material>
    </visual>
    <collision>
      <origin
        xyz="0 0 0"
        rpy="0 0 0" />
      <geometry>
        <mesh
          filename="package://robot_description/airbot/meshes/link1.STL" />
      </geometry>
    </collision>
  </link>
  <joint
    name="joint1"
    type="revolute">
    <origin
      xyz="0 0 0.1172"
      rpy="0 0 0" />
    <parent
      link="base_link" />
    <child
      link="link1" />
    <axis
      xyz="0 0 1" />
    <limit
      lower="-3.14"
      upper="2.09"
      effort="18"
      velocity="3.14" />
  </joint>
  <link
    name="link2">
    <inertial>
      <origin
        xyz="0.22493 0.0047721 0.008023"
        rpy="0 0 0" />
      <mass
        value="0.64621" />
      <inertia
        ixx="0.0004901"
        ixy="-0.0002434"
        ixz="-0.0005229"
        iyy="0.0051052"
        iyz="2.95E-05"
        izz="0.0050391" />
    </inertial>
    <visual>
      <origin
        xyz="0 0 0"
        rpy="0 0 0" />
      <geometry>
        <mesh
          filename="package://robot_description/airbot/meshes/link2.STL" />
      </geometry>
      <material
        name="">
        <color
          rgba="0.75294 0.75294 0.75294 1" />
      </material>
    </visual>
    <collision>
      <origin
        xyz="0 0 0"
        rpy="0 0 0" />
      <geometry>
        <mesh
          filename="package://robot_description/airbot/meshes/link2.STL" />
      </geometry>
    </collision>
  </link>
  <joint
    name="joint2"
    type="revolute">
    <origin
      xyz="0 0 0"
      rpy="1.5708 -2.7549 0" />
    <parent
      link="link1" />
    <child
      link="link2" />
    <axis
      xyz="0 0 1" />
    <limit
      lower="-2.96"
      upper="0.17"
      effort="18"
      velocity="3.14" />
  </joint>
  <link
    name="link3">
    <inertial>
      <origin
        xyz="0.16813 -5.5576E-05 0.0031184"
        rpy="0 0 0" />
      <mass
        value="0.26829" />
      <inertia
        ixx="0.0001667"
        ixy="-7E-07"
        ixz="-0.0001113"
        iyy="0.0026816"
        iyz="-1E-07"
        izz="0.002619" />
    </inertial>
    <visual>
      <origin
        xyz="0 0 0"
        rpy="0 0 0" />
      <geometry>
        <mesh
          filename="package://robot_description/airbot/meshes/link3.STL" />
      </geometry>
      <material
        name="">
        <color
          rgba="0.75294 0.75294 0.75294 1" />
      </material>
    </visual>
    <collision>
      <origin
        xyz="0 0 0"
        rpy="0 0 0" />
      <geometry>
        <mesh
          filename="package://robot_description/airbot/meshes/link3.STL" />
      </geometry>
    </collision>
  </link>
  <joint
    name="joint3"
    type="revolute">
    <origin
      xyz="0.27009 0 0"
      rpy="0 0 -2.7549" />
    <parent
      link="link2" />
    <child
      link="link3" />
    <axis
      xyz="0 0 1" />
    <limit
      lower="-0.087"
      upper="3.14"
      effort="18"
      velocity="3.14" />
  </joint>
  <link
    name="link4">
    <inertial>
      <origin
        xyz="5.2436E-06 0.00040412 -0.03228"
        rpy="0 0 0" />
      <mass
        value="0.34876" />
      <inertia
        ixx="0.0001074"
        ixy="0"
        ixz="0"
        iyy="0.000119"
        iyz="1E-06"
        izz="8.83E-05" />
    </inertial>
    <visual>
      <origin
        xyz="0 0 0"
        rpy="0 0 0" />
      <geometry>
        <mesh
          filename="package://robot_description/airbot/meshes/link4.STL" />
      </geometry>
      <material
        name="">
        <color
          rgba="1 1 1 1" />
      </material>
    </visual>
    <collision>
      <origin
        xyz="0 0 0"
        rpy="0 0 0" />
      <geometry>
        <mesh
          filename="package://robot_description/airbot/meshes/link4.STL" />
      </geometry>
    </collision>
  </link>
  <joint
    name="joint4"
    type="revolute">
    <origin
      xyz="0.30854 0 0"
      rpy="3.1416 -1.5708 0" />
    <parent
      link="link3" />
    <child
      link="link4" />
    <axis
      xyz="0 0 1" />
    <limit
      lower="-2.96"
      upper="2.96"
      effort="3"
      velocity="6.28" />
  </joint>
  <link
    name="link5">
    <inertial>
      <origin
        xyz="8.3318E-06 0.026148 0.002525"
        rpy="0 0 0" />
      <mass
        value="0.36132" />
      <inertia
        ixx="0.0004676"
        ixy="0"
        ixz="0"
        iyy="0.0001825"
        iyz="-3.29E-05"
        izz="0.0004286" />
    </inertial>
    <visual>
      <origin
        xyz="0 0 0"
        rpy="0 0 0" />
      <geometry>
        <mesh
          filename="package://robot_description/airbot/meshes/link5.STL" />
      </geometry>
      <material
        name="">
        <color
          rgba="0.89804 0.91765 0.92941 1" />
      </material>
    </visual>
    <collision>
      <origin
        xyz="0 0 0"
        rpy="0 0 0" />
      <geometry>
        <mesh
          filename="package://robot_description/airbot/meshes/link5.STL" />
      </geometry>
    </collision>
  </link>
  <joint
    name="joint5"
    type="revolute">
    <origin
      xyz="0 0 0"
      rpy="1.5708 0 0" />
    <parent
      link="link4" />
    <child
      link="link5" />
    <axis
      xyz="0 0 1" />
    <limit
      lower="-1.74"
      upper="1.74"
      effort="3"
      velocity="6.28" />
  </joint>
  <link
    name="link6">
    <inertial>
      <origin
        xyz="0.020482 2.5483E-05 -0.079685"
        rpy="0 0 0" />
      <mass
        value="0.80081" />
      <inertia
        ixx="0.0011915"
        ixy="-5.7E-06"
        ixz="0.0002989"
        iyy="0.0020617"
        iyz="9E-07"
        izz="0.0011889" />
    </inertial>
    <visual>
      <origin
        xyz="0 0 0"
        rpy="0 0 0" />
      <geometry>
        <mesh
          filename="package://robot_description/airbot/meshes/link6.STL" />
      </geometry>
      <material
        name="">
        <color
          rgba="0.75294 0.75294 0.75294 1" />
      </material>
    </visual>
    <collision>
      <origin
        xyz="0 0 0"
        rpy="0 0 0" />
      <geometry>
        <mesh
          filename="package://robot_description/airbot/meshes/link6.STL" />
      </geometry>
    </collision>
  </link>
  <joint
    name="joint6"
    type="revolute">
    <origin
      xyz="0 0.19608 0"
      rpy="-1.5708 1.5708 0" />
    <parent
      link="link5" />
    <child
      link="link6" />
    <axis
      xyz="0 0 1" />
    <limit
      lower="-3.14"
      upper="3.14"
      effort="3"
      velocity="6.28" />
  </joint>
</robot>